<sdf version='1.7'>
  <model name='quadruped'>
    <link name='base_link'>
      <inertial>
        <pose>0 0 0 0 -0 0</pose>
        <mass>0.5</mass>
        <inertia>
          <ixx>0.000542083</ixx>
          <ixy>0</ixy>
          <ixz>0</ixz>
          <iyy>0.00142242</iyy>
          <iyz>0</iyz>
          <izz>0.00173042</izz>
        </inertia>
      </inertial>
      <collision name='base_link_collision'>
        <pose>0 0 0 0 -0 0</pose>
        <geometry>
          <box>
            <size>0.177 0.101 0.053</size>
          </box>
        </geometry>
        <surface>
          <contact>
            <ode/>
          </contact>
          <friction>
            <ode/>
          </friction>
        </surface>
      </collision>
      <visual name='base_link_visual'>
        <pose>0 0 -0.0265 0 -0 0</pose>
        <geometry>
          <mesh>
            <scale>1 1 1</scale>
            <uri>model://quadruped/meshes/hexapod_body.stl</uri>
          </mesh>
        </geometry>
        <material>
          <script>
            <name>Gazebo/DarkGray</name>
            <uri>file://media/materials/scripts/gazebo.material</uri>
          </script>
        </material>
      </visual>
      <gravity>1</gravity>
      <velocity_decay/>
    </link>
    <joint name='coxa_bl_joint' type='revolute'>
      <pose relative_to='base_link'>-0.0885 0.0505 0 0 -0 2.35619</pose>
      <parent>base_link</parent>
      <child>coxa_bl_link</child>
      <axis>
        <xyz>0 0 1</xyz>
        <limit>
          <lower>-1.5708</lower>
          <upper>1.5708</upper>
          <effort>100</effort>
          <velocity>0.5</velocity>
        </limit>
        <dynamics>
          <spring_reference>0</spring_reference>
          <spring_stiffness>0</spring_stiffness>
        </dynamics>
      </axis>
      <physics>
        <ode>
          <limit>
            <cfm>0</cfm>
            <erp>0.2</erp>
          </limit>
        </ode>
      </physics>
    </joint>
    <link name='coxa_bl_link'>
      <pose relative_to='coxa_bl_joint'>0 0 0 0 -0 0</pose>
      <inertial>
        <pose>0.01425 0 0 0 1.5708 0</pose>
        <mass>0.1</mass>
        <inertia>
          <ixx>9.26875e-06</ixx>
          <ixy>0</ixy>
          <ixz>0</ixz>
          <iyy>9.26875e-06</iyy>
          <iyz>0</iyz>
          <izz>5e-06</izz>
        </inertia>
      </inertial>
      <collision name='coxa_bl_link_collision'>
        <pose>0.01425 0 0 0 1.5708 0</pose>
        <geometry>
          <cylinder>
            <length>0.0285</length>
            <radius>0.01</radius>
          </cylinder>
        </geometry>
        <surface>
          <contact>
            <ode/>
          </contact>
          <friction>
            <ode/>
          </friction>
        </surface>
      </collision>
      <visual name='coxa_bl_link_visual'>
        <pose>0 0 0.0196 0 -0 0</pose>
        <geometry>
          <mesh>
            <scale>1 1 1</scale>
            <uri>model://quadruped/meshes/hexapod_coxa_l.stl</uri>
          </mesh>
        </geometry>
        <material>
          <script>
            <name>Gazebo/DarkGray</name>
            <uri>file://media/materials/scripts/gazebo.material</uri>
          </script>
        </material>
      </visual>
      <gravity>1</gravity>
      <velocity_decay/>
    </link>
    <joint name='femur_bl_joint' type='revolute'>
      <pose relative_to='coxa_bl_link'>0.0285 0 0 0 -0 0</pose>
      <parent>coxa_bl_link</parent>
      <child>femur_bl_link</child>
      <axis>
        <xyz>0 1 0</xyz>
        <limit>
          <lower>-1.5708</lower>
          <upper>1.5708</upper>
          <effort>100</effort>
          <velocity>0.5</velocity>
        </limit>
        <dynamics>
          <spring_reference>0</spring_reference>
          <spring_stiffness>0</spring_stiffness>
        </dynamics>
      </axis>
      <physics>
        <ode>
          <limit>
            <cfm>0</cfm>
            <erp>0.2</erp>
          </limit>
        </ode>
      </physics>
    </joint>
    <link name='femur_bl_link'>
      <pose relative_to='femur_bl_joint'>0 0 0 0 -0 0</pose>
      <inertial>
        <pose>0.0381 0 0 0 1.5708 0</pose>
        <mass>0.1</mass>
        <inertia>
          <ixx>5.0887e-05</ixx>
          <ixy>0</ixy>
          <ixz>0</ixz>
          <iyy>5.0887e-05</iyy>
          <iyz>0</iyz>
          <izz>5e-06</izz>
        </inertia>
      </inertial>
      <collision name='femur_bl_link_collision'>
        <pose>0.0381 0 0 0 1.5708 0</pose>
        <geometry>
          <cylinder>
            <length>0.0762</length>
            <radius>0.01</radius>
          </cylinder>
        </geometry>
        <surface>
          <contact>
            <ode/>
          </contact>
          <friction>
            <ode/>
          </friction>
        </surface>
      </collision>
      <visual name='femur_bl_link_visual'>
        <pose>0 -0.026 0 0 -0 0</pose>
        <geometry>
          <mesh>
            <scale>1 1 1</scale>
            <uri>model://quadruped/meshes/hexapod_femur_l.stl</uri>
          </mesh>
        </geometry>
        <material>
          <script>
            <name>Gazebo/DarkGray</name>
            <uri>file://media/materials/scripts/gazebo.material</uri>
          </script>
        </material>
      </visual>
      <gravity>1</gravity>
      <velocity_decay/>
    </link>
    <joint name='tibia_bl_joint' type='revolute'>
      <pose relative_to='femur_bl_link'>0.0762 0 0 0 -0 0</pose>
      <parent>femur_bl_link</parent>
      <child>tibia_bl_link</child>
      <axis>
        <xyz>0 1 0</xyz>
        <limit>
          <lower>-1.5708</lower>
          <upper>1.5708</upper>
          <effort>100</effort>
          <velocity>0.5</velocity>
        </limit>
        <dynamics>
          <spring_reference>0</spring_reference>
          <spring_stiffness>0</spring_stiffness>
        </dynamics>
      </axis>
      <physics>
        <ode>
          <limit>
            <cfm>0</cfm>
            <erp>0.2</erp>
          </limit>
        </ode>
      </physics>
    </joint>
    <link name='tibia_bl_link'>
      <pose relative_to='tibia_bl_joint'>0 0 0 0 -0 0</pose>
      <inertial>
        <pose>0 0 -0.068 0 -0 0</pose>
        <mass>0.15</mass>
        <inertia>
          <ixx>0.0001779</ixx>
          <ixy>0</ixy>
          <ixz>0</ixz>
          <iyy>0.0001779</iyy>
          <iyz>0</iyz>
          <izz>7e-06</izz>
        </inertia>
      </inertial>
      <collision name='tibia_bl_link_collision'>
        <pose>0 0 -0.051 0 -0 0</pose>
        <geometry>
          <cylinder>
            <length>0.102</length>
            <radius>0.01</radius>
          </cylinder>
        </geometry>
        <surface>
          <contact>
            <ode/>
          </contact>
          <friction>
            <ode/>
          </friction>
        </surface>
      </collision>
      <collision name='tibia_bl_link_fixed_joint_lump__foot_bl_link_collision_1'>
        <pose>0 0 -0.102 0 -0 0</pose>
        <geometry>
          <sphere>
            <radius>0.01</radius>
          </sphere>
        </geometry>
        <surface>
          <contact>
            <ode/>
          </contact>
          <friction>
            <ode>
              <mu>1</mu>
              <mu2>1</mu2>
            </ode>
          </friction>
        </surface>
      </collision>
      <visual name='tibia_bl_link_visual'>
        <pose>0 -0.0185 0 0 -0 0</pose>
        <geometry>
          <mesh>
            <scale>1 1 1</scale>
            <uri>model://quadruped/meshes/hexapod_tibia_l.stl</uri>
          </mesh>
        </geometry>
        <material>
          <script>
            <name>Gazebo/DarkGray</name>
            <uri>file://media/materials/scripts/gazebo.material</uri>
          </script>
        </material>
      </visual>
      <velocity_decay/>
      <gravity>1</gravity>
      <velocity_decay/>
    </link>
    <joint name='coxa_br_joint' type='revolute'>
      <pose relative_to='base_link'>-0.0885 -0.0505 0 0 0 -2.35619</pose>
      <parent>base_link</parent>
      <child>coxa_br_link</child>
      <axis>
        <xyz>0 0 1</xyz>
        <limit>
          <lower>-1.5708</lower>
          <upper>1.5708</upper>
          <effort>100</effort>
          <velocity>0.5</velocity>
        </limit>
        <dynamics>
          <spring_reference>0</spring_reference>
          <spring_stiffness>0</spring_stiffness>
        </dynamics>
      </axis>
      <physics>
        <ode>
          <limit>
            <cfm>0</cfm>
            <erp>0.2</erp>
          </limit>
        </ode>
      </physics>
    </joint>
    <link name='coxa_br_link'>
      <pose relative_to='coxa_br_joint'>0 0 0 0 -0 0</pose>
      <inertial>
        <pose>0.01425 0 0 0 1.5708 0</pose>
        <mass>0.1</mass>
        <inertia>
          <ixx>9.26875e-06</ixx>
          <ixy>0</ixy>
          <ixz>0</ixz>
          <iyy>9.26875e-06</iyy>
          <iyz>0</iyz>
          <izz>5e-06</izz>
        </inertia>
      </inertial>
      <collision name='coxa_br_link_collision'>
        <pose>0.01425 0 0 0 1.5708 0</pose>
        <geometry>
          <cylinder>
            <length>0.0285</length>
            <radius>0.01</radius>
          </cylinder>
        </geometry>
        <surface>
          <contact>
            <ode/>
          </contact>
          <friction>
            <ode/>
          </friction>
        </surface>
      </collision>
      <visual name='coxa_br_link_visual'>
        <pose>0 0 0.0196 0 -0 0</pose>
        <geometry>
          <mesh>
            <scale>1 1 1</scale>
            <uri>model://quadruped/meshes/hexapod_coxa_r.stl</uri>
          </mesh>
        </geometry>
        <material>
          <script>
            <name>Gazebo/DarkGray</name>
            <uri>file://media/materials/scripts/gazebo.material</uri>
          </script>
        </material>
      </visual>
      <gravity>1</gravity>
      <velocity_decay/>
    </link>
    <joint name='femur_br_joint' type='revolute'>
      <pose relative_to='coxa_br_link'>0.0285 0 0 0 -0 0</pose>
      <parent>coxa_br_link</parent>
      <child>femur_br_link</child>
      <axis>
        <xyz>0 1 0</xyz>
        <limit>
          <lower>-1.5708</lower>
          <upper>1.5708</upper>
          <effort>100</effort>
          <velocity>0.5</velocity>
        </limit>
        <dynamics>
          <spring_reference>0</spring_reference>
          <spring_stiffness>0</spring_stiffness>
        </dynamics>
      </axis>
      <physics>
        <ode>
          <limit>
            <cfm>0</cfm>
            <erp>0.2</erp>
          </limit>
        </ode>
      </physics>
    </joint>
    <link name='femur_br_link'>
      <pose relative_to='femur_br_joint'>0 0 0 0 -0 0</pose>
      <inertial>
        <pose>0.0381 0 0 0 1.5708 0</pose>
        <mass>0.1</mass>
        <inertia>
          <ixx>5.0887e-05</ixx>
          <ixy>0</ixy>
          <ixz>0</ixz>
          <iyy>5.0887e-05</iyy>
          <iyz>0</iyz>
          <izz>5e-06</izz>
        </inertia>
      </inertial>
      <collision name='femur_br_link_collision'>
        <pose>0.0381 0 0 0 1.5708 0</pose>
        <geometry>
          <cylinder>
            <length>0.0762</length>
            <radius>0.01</radius>
          </cylinder>
        </geometry>
        <surface>
          <contact>
            <ode/>
          </contact>
          <friction>
            <ode/>
          </friction>
        </surface>
      </collision>
      <visual name='femur_br_link_visual'>
        <pose>0 0.026 0 0 -0 0</pose>
        <geometry>
          <mesh>
            <scale>1 1 1</scale>
            <uri>model://quadruped/meshes/hexapod_femur_r.stl</uri>
          </mesh>
        </geometry>
        <material>
          <script>
            <name>Gazebo/DarkGray</name>
            <uri>file://media/materials/scripts/gazebo.material</uri>
          </script>
        </material>
      </visual>
      <gravity>1</gravity>
      <velocity_decay/>
    </link>
    <joint name='tibia_br_joint' type='revolute'>
      <pose relative_to='femur_br_link'>0.0762 0 0 0 -0 0</pose>
      <parent>femur_br_link</parent>
      <child>tibia_br_link</child>
      <axis>
        <xyz>0 1 0</xyz>
        <limit>
          <lower>-1.5708</lower>
          <upper>1.5708</upper>
          <effort>100</effort>
          <velocity>0.5</velocity>
        </limit>
        <dynamics>
          <spring_reference>0</spring_reference>
          <spring_stiffness>0</spring_stiffness>
        </dynamics>
      </axis>
      <physics>
        <ode>
          <limit>
            <cfm>0</cfm>
            <erp>0.2</erp>
          </limit>
        </ode>
      </physics>
    </joint>
    <link name='tibia_br_link'>
      <pose relative_to='tibia_br_joint'>0 0 0 0 -0 0</pose>
      <inertial>
        <pose>0 0 -0.068 0 -0 0</pose>
        <mass>0.15</mass>
        <inertia>
          <ixx>0.0001779</ixx>
          <ixy>0</ixy>
          <ixz>0</ixz>
          <iyy>0.0001779</iyy>
          <iyz>0</iyz>
          <izz>7e-06</izz>
        </inertia>
      </inertial>
      <collision name='tibia_br_link_collision'>
        <pose>0 0 -0.051 0 -0 0</pose>
        <geometry>
          <cylinder>
            <length>0.102</length>
            <radius>0.01</radius>
          </cylinder>
        </geometry>
        <surface>
          <contact>
            <ode/>
          </contact>
          <friction>
            <ode/>
          </friction>
        </surface>
      </collision>
      <collision name='tibia_br_link_fixed_joint_lump__foot_br_link_collision_1'>
        <pose>0 0 -0.102 0 -0 0</pose>
        <geometry>
          <sphere>
            <radius>0.01</radius>
          </sphere>
        </geometry>
        <surface>
          <contact>
            <ode/>
          </contact>
          <friction>
            <ode>
              <mu>1</mu>
              <mu2>1</mu2>
            </ode>
          </friction>
        </surface>
      </collision>
      <visual name='tibia_br_link_visual'>
        <pose>0 0.0185 0 0 -0 0</pose>
        <geometry>
          <mesh>
            <scale>1 1 1</scale>
            <uri>model://quadruped/meshes/hexapod_tibia_r.stl</uri>
          </mesh>
        </geometry>
        <material>
          <script>
            <name>Gazebo/DarkGray</name>
            <uri>file://media/materials/scripts/gazebo.material</uri>
          </script>
        </material>
      </visual>
      <velocity_decay/>
      <gravity>1</gravity>
      <velocity_decay/>
    </link>
    <joint name='coxa_fl_joint' type='revolute'>
      <pose relative_to='base_link'>0.0885 0.0505 0 0 -0 0.785398</pose>
      <parent>base_link</parent>
      <child>coxa_fl_link</child>
      <axis>
        <xyz>0 0 1</xyz>
        <limit>
          <lower>-1.5708</lower>
          <upper>1.5708</upper>
          <effort>100</effort>
          <velocity>0.5</velocity>
        </limit>
        <dynamics>
          <spring_reference>0</spring_reference>
          <spring_stiffness>0</spring_stiffness>
        </dynamics>
      </axis>
      <physics>
        <ode>
          <limit>
            <cfm>0</cfm>
            <erp>0.2</erp>
          </limit>
        </ode>
      </physics>
    </joint>
    <link name='coxa_fl_link'>
      <pose relative_to='coxa_fl_joint'>0 0 0 0 -0 0</pose>
      <inertial>
        <pose>0.01425 0 0 0 1.5708 0</pose>
        <mass>0.1</mass>
        <inertia>
          <ixx>9.26875e-06</ixx>
          <ixy>0</ixy>
          <ixz>0</ixz>
          <iyy>9.26875e-06</iyy>
          <iyz>0</iyz>
          <izz>5e-06</izz>
        </inertia>
      </inertial>
      <collision name='coxa_fl_link_collision'>
        <pose>0.01425 0 0 0 1.5708 0</pose>
        <geometry>
          <cylinder>
            <length>0.0285</length>
            <radius>0.01</radius>
          </cylinder>
        </geometry>
        <surface>
          <contact>
            <ode/>
          </contact>
          <friction>
            <ode/>
          </friction>
        </surface>
      </collision>
      <visual name='coxa_fl_link_visual'>
        <pose>0 0 0.0196 0 -0 0</pose>
        <geometry>
          <mesh>
            <scale>1 1 1</scale>
            <uri>model://quadruped/meshes/hexapod_coxa_l.stl</uri>
          </mesh>
        </geometry>
        <material>
          <script>
            <name>Gazebo/DarkGray</name>
            <uri>file://media/materials/scripts/gazebo.material</uri>
          </script>
        </material>
      </visual>
      <gravity>1</gravity>
      <velocity_decay/>
    </link>
    <joint name='femur_fl_joint' type='revolute'>
      <pose relative_to='coxa_fl_link'>0.0285 0 0 0 -0 0</pose>
      <parent>coxa_fl_link</parent>
      <child>femur_fl_link</child>
      <axis>
        <xyz>0 1 0</xyz>
        <limit>
          <lower>-1.5708</lower>
          <upper>1.5708</upper>
          <effort>100</effort>
          <velocity>0.5</velocity>
        </limit>
        <dynamics>
          <spring_reference>0</spring_reference>
          <spring_stiffness>0</spring_stiffness>
        </dynamics>
      </axis>
      <physics>
        <ode>
          <limit>
            <cfm>0</cfm>
            <erp>0.2</erp>
          </limit>
        </ode>
      </physics>
    </joint>
    <link name='femur_fl_link'>
      <pose relative_to='femur_fl_joint'>0 0 0 0 -0 0</pose>
      <inertial>
        <pose>0.0381 0 0 0 1.5708 0</pose>
        <mass>0.1</mass>
        <inertia>
          <ixx>5.0887e-05</ixx>
          <ixy>0</ixy>
          <ixz>0</ixz>
          <iyy>5.0887e-05</iyy>
          <iyz>0</iyz>
          <izz>5e-06</izz>
        </inertia>
      </inertial>
      <collision name='femur_fl_link_collision'>
        <pose>0.0381 0 0 0 1.5708 0</pose>
        <geometry>
          <cylinder>
            <length>0.0762</length>
            <radius>0.01</radius>
          </cylinder>
        </geometry>
        <surface>
          <contact>
            <ode/>
          </contact>
          <friction>
            <ode/>
          </friction>
        </surface>
      </collision>
      <visual name='femur_fl_link_visual'>
        <pose>0 -0.026 0 0 -0 0</pose>
        <geometry>
          <mesh>
            <scale>1 1 1</scale>
            <uri>model://quadruped/meshes/hexapod_femur_l.stl</uri>
          </mesh>
        </geometry>
        <material>
          <script>
            <name>Gazebo/DarkGray</name>
            <uri>file://media/materials/scripts/gazebo.material</uri>
          </script>
        </material>
      </visual>
      <gravity>1</gravity>
      <velocity_decay/>
    </link>
    <joint name='tibia_fl_joint' type='revolute'>
      <pose relative_to='femur_fl_link'>0.0762 0 0 0 -0 0</pose>
      <parent>femur_fl_link</parent>
      <child>tibia_fl_link</child>
      <axis>
        <xyz>0 1 0</xyz>
        <limit>
          <lower>-1.5708</lower>
          <upper>1.5708</upper>
          <effort>100</effort>
          <velocity>0.5</velocity>
        </limit>
        <dynamics>
          <spring_reference>0</spring_reference>
          <spring_stiffness>0</spring_stiffness>
        </dynamics>
      </axis>
      <physics>
        <ode>
          <limit>
            <cfm>0</cfm>
            <erp>0.2</erp>
          </limit>
        </ode>
      </physics>
    </joint>
    <link name='tibia_fl_link'>
      <pose relative_to='tibia_fl_joint'>0 0 0 0 -0 0</pose>
      <inertial>
        <pose>0 0 -0.068 0 -0 0</pose>
        <mass>0.15</mass>
        <inertia>
          <ixx>0.0001779</ixx>
          <ixy>0</ixy>
          <ixz>0</ixz>
          <iyy>0.0001779</iyy>
          <iyz>0</iyz>
          <izz>7e-06</izz>
        </inertia>
      </inertial>
      <collision name='tibia_fl_link_collision'>
        <pose>0 0 -0.051 0 -0 0</pose>
        <geometry>
          <cylinder>
            <length>0.102</length>
            <radius>0.01</radius>
          </cylinder>
        </geometry>
        <surface>
          <contact>
            <ode/>
          </contact>
          <friction>
            <ode/>
          </friction>
        </surface>
      </collision>
      <collision name='tibia_fl_link_fixed_joint_lump__foot_fl_link_collision_1'>
        <pose>0 0 -0.102 0 -0 0</pose>
        <geometry>
          <sphere>
            <radius>0.01</radius>
          </sphere>
        </geometry>
        <surface>
          <contact>
            <ode/>
          </contact>
          <friction>
            <ode>
              <mu>1</mu>
              <mu2>1</mu2>
            </ode>
          </friction>
        </surface>
      </collision>
      <visual name='tibia_fl_link_visual'>
        <pose>0 -0.0185 0 0 -0 0</pose>
        <geometry>
          <mesh>
            <scale>1 1 1</scale>
            <uri>model://quadruped/meshes/hexapod_tibia_l.stl</uri>
          </mesh>
        </geometry>
        <material>
          <script>
            <name>Gazebo/DarkGray</name>
            <uri>file://media/materials/scripts/gazebo.material</uri>
          </script>
        </material>
      </visual>
      <velocity_decay/>
      <gravity>1</gravity>
      <velocity_decay/>
    </link>
    <joint name='coxa_fr_joint' type='revolute'>
      <pose relative_to='base_link'>0.0885 -0.0505 0 0 0 -0.785398</pose>
      <parent>base_link</parent>
      <child>coxa_fr_link</child>
      <axis>
        <xyz>0 0 1</xyz>
        <limit>
          <lower>-1.5708</lower>
          <upper>1.5708</upper>
          <effort>100</effort>
          <velocity>0.5</velocity>
        </limit>
        <dynamics>
          <spring_reference>0</spring_reference>
          <spring_stiffness>0</spring_stiffness>
        </dynamics>
      </axis>
      <physics>
        <ode>
          <limit>
            <cfm>0</cfm>
            <erp>0.2</erp>
          </limit>
        </ode>
      </physics>
    </joint>
    <link name='coxa_fr_link'>
      <pose relative_to='coxa_fr_joint'>0 0 0 0 -0 0</pose>
      <inertial>
        <pose>0.01425 0 0 0 1.5708 0</pose>
        <mass>0.1</mass>
        <inertia>
          <ixx>9.26875e-06</ixx>
          <ixy>0</ixy>
          <ixz>0</ixz>
          <iyy>9.26875e-06</iyy>
          <iyz>0</iyz>
          <izz>5e-06</izz>
        </inertia>
      </inertial>
      <collision name='coxa_fr_link_collision'>
        <pose>0.01425 0 0 0 1.5708 0</pose>
        <geometry>
          <cylinder>
            <length>0.0285</length>
            <radius>0.01</radius>
          </cylinder>
        </geometry>
        <surface>
          <contact>
            <ode/>
          </contact>
          <friction>
            <ode/>
          </friction>
        </surface>
      </collision>
      <visual name='coxa_fr_link_visual'>
        <pose>0 0 0.0196 0 -0 0</pose>
        <geometry>
          <mesh>
            <scale>1 1 1</scale>
            <uri>model://quadruped/meshes/hexapod_coxa_r.stl</uri>
          </mesh>
        </geometry>
        <material>
          <script>
            <name>Gazebo/DarkGray</name>
            <uri>file://media/materials/scripts/gazebo.material</uri>
          </script>
        </material>
      </visual>
      <gravity>1</gravity>
      <velocity_decay/>
    </link>
    <joint name='femur_fr_joint' type='revolute'>
      <pose relative_to='coxa_fr_link'>0.0285 0 0 0 -0 0</pose>
      <parent>coxa_fr_link</parent>
      <child>femur_fr_link</child>
      <axis>
        <xyz>0 1 0</xyz>
        <limit>
          <lower>-1.5708</lower>
          <upper>1.5708</upper>
          <effort>100</effort>
          <velocity>0.5</velocity>
        </limit>
        <dynamics>
          <spring_reference>0</spring_reference>
          <spring_stiffness>0</spring_stiffness>
        </dynamics>
      </axis>
      <physics>
        <ode>
          <limit>
            <cfm>0</cfm>
            <erp>0.2</erp>
          </limit>
        </ode>
      </physics>
    </joint>
    <link name='femur_fr_link'>
      <pose relative_to='femur_fr_joint'>0 0 0 0 -0 0</pose>
      <inertial>
        <pose>0.0381 0 0 0 1.5708 0</pose>
        <mass>0.1</mass>
        <inertia>
          <ixx>5.0887e-05</ixx>
          <ixy>0</ixy>
          <ixz>0</ixz>
          <iyy>5.0887e-05</iyy>
          <iyz>0</iyz>
          <izz>5e-06</izz>
        </inertia>
      </inertial>
      <collision name='femur_fr_link_collision'>
        <pose>0.0381 0 0 0 1.5708 0</pose>
        <geometry>
          <cylinder>
            <length>0.0762</length>
            <radius>0.01</radius>
          </cylinder>
        </geometry>
        <surface>
          <contact>
            <ode/>
          </contact>
          <friction>
            <ode/>
          </friction>
        </surface>
      </collision>
      <visual name='femur_fr_link_visual'>
        <pose>0 0.026 0 0 -0 0</pose>
        <geometry>
          <mesh>
            <scale>1 1 1</scale>
            <uri>model://quadruped/meshes/hexapod_femur_r.stl</uri>
          </mesh>
        </geometry>
        <material>
          <script>
            <name>Gazebo/DarkGray</name>
            <uri>file://media/materials/scripts/gazebo.material</uri>
          </script>
        </material>
      </visual>
      <gravity>1</gravity>
      <velocity_decay/>
    </link>
    <joint name='tibia_fr_joint' type='revolute'>
      <pose relative_to='femur_fr_link'>0.0762 0 0 0 -0 0</pose>
      <parent>femur_fr_link</parent>
      <child>tibia_fr_link</child>
      <axis>
        <xyz>0 1 0</xyz>
        <limit>
          <lower>-1.5708</lower>
          <upper>1.5708</upper>
          <effort>100</effort>
          <velocity>0.5</velocity>
        </limit>
        <dynamics>
          <spring_reference>0</spring_reference>
          <spring_stiffness>0</spring_stiffness>
        </dynamics>
      </axis>
      <physics>
        <ode>
          <limit>
            <cfm>0</cfm>
            <erp>0.2</erp>
          </limit>
        </ode>
      </physics>
    </joint>
    <link name='tibia_fr_link'>
      <pose relative_to='tibia_fr_joint'>0 0 0 0 -0 0</pose>
      <inertial>
        <pose>0 0 -0.068 0 -0 0</pose>
        <mass>0.15</mass>
        <inertia>
          <ixx>0.0001779</ixx>
          <ixy>0</ixy>
          <ixz>0</ixz>
          <iyy>0.0001779</iyy>
          <iyz>0</iyz>
          <izz>7e-06</izz>
        </inertia>
      </inertial>
      <collision name='tibia_fr_link_collision'>
        <pose>0 0 -0.051 0 -0 0</pose>
        <geometry>
          <cylinder>
            <length>0.102</length>
            <radius>0.01</radius>
          </cylinder>
        </geometry>
        <surface>
          <contact>
            <ode/>
          </contact>
          <friction>
            <ode/>
          </friction>
        </surface>
      </collision>
      <collision name='tibia_fr_link_fixed_joint_lump__foot_fr_link_collision_1'>
        <pose>0 0 -0.102 0 -0 0</pose>
        <geometry>
          <sphere>
            <radius>0.01</radius>
          </sphere>
        </geometry>
        <surface>
          <contact>
            <ode/>
          </contact>
          <friction>
            <ode>
              <mu>1</mu>
              <mu2>1</mu2>
            </ode>
          </friction>
        </surface>
      </collision>
      <visual name='tibia_fr_link_visual'>
        <pose>0 0.0185 0 0 -0 0</pose>
        <geometry>
          <mesh>
            <scale>1 1 1</scale>
            <uri>model://quadruped/meshes/hexapod_tibia_r.stl</uri>
          </mesh>
        </geometry>
        <material>
          <script>
            <name>Gazebo/DarkGray</name>
            <uri>file://media/materials/scripts/gazebo.material</uri>
          </script>
        </material>
      </visual>
      <velocity_decay/>
      <gravity>1</gravity>
      <velocity_decay/>
    </link>
  </model>
</sdf>
