<sdf version='1.7'>
  <model name='steer_bot'>
    <link name='base_link'>
      <inertial>
        <pose>0 0 0 0 -0 0</pose>
        <mass>5</mass>
        <inertia>
          <ixx>0.0416667</ixx>
          <ixy>0</ixy>
          <ixz>0</ixz>
          <iyy>0.108333</iyy>
          <iyz>0</iyz>
          <izz>0.141667</izz>
        </inertia>
      </inertial>
      <collision name='base_link_collision'>
        <pose>0 0 0 0 -0 0</pose>
        <geometry>
          <box>
            <size>0.5 0.3 0.1</size>
          </box>
        </geometry>
        <surface>
          <contact>
            <ode/>
          </contact>
          <friction>
            <ode/>
          </friction>
        </surface>
      </collision>
      <visual name='base_link_visual'>
        <pose>0 0 0 0 -0 0</pose>
        <geometry>
          <box>
            <size>0.5 0.3 0.1</size>
          </box>
        </geometry>
        <material>
          <script>
            <name>Gazebo/Green</name>
            <uri>file://media/materials/scripts/gazebo.material</uri>
          </script>
        </material>
      </visual>
      <gravity>1</gravity>
      <velocity_decay/>
    </link>
    <joint name='front_left_steer_joint' type='revolute'>
      <pose relative_to='base_link'>0.2 0.2 0.12 0 -0 0</pose>
      <parent>base_link</parent>
      <child>front_left_steer_link</child>
      <axis>
        <xyz>0 0 1</xyz>
        <limit>
          <lower>-0.785398</lower>
          <upper>0.785398</upper>
          <effort>10</effort>
          <velocity>5</velocity>
        </limit>
        <dynamics>
          <spring_reference>0</spring_reference>
          <spring_stiffness>0</spring_stiffness>
        </dynamics>
      </axis>
    </joint>
    <link name='front_left_steer_link'>
      <pose relative_to='front_left_steer_joint'>0 0 0 0 -0 0</pose>
      <inertial>
        <pose>0 0 0 0 -0 0</pose>
        <mass>1</mass>
        <inertia>
          <ixx>0.000658333</ixx>
          <ixy>0</ixy>
          <ixz>0</ixz>
          <iyy>0.000658333</iyy>
          <iyz>0</iyz>
          <izz>0.00125</izz>
        </inertia>
      </inertial>
      <collision name='front_left_steer_link_collision'>
        <pose>0 0 0 0 -0 0</pose>
        <geometry>
          <cylinder>
            <length>0.02</length>
            <radius>0.05</radius>
          </cylinder>
        </geometry>
        <surface>
          <contact>
            <ode/>
          </contact>
          <friction>
            <ode/>
          </friction>
        </surface>
      </collision>
      <visual name='front_left_steer_link_visual'>
        <pose>0 0 0 0 -0 0</pose>
        <geometry>
          <cylinder>
            <length>0.02</length>
            <radius>0.05</radius>
          </cylinder>
        </geometry>
        <material>
          <script>
            <name>Gazebo/Blue</name>
            <uri>file://media/materials/scripts/gazebo.material</uri>
          </script>
        </material>
      </visual>
      <gravity>1</gravity>
      <velocity_decay/>
    </link>
    <joint name='front_left_wheel_joint' type='revolute'>
      <pose relative_to='front_left_steer_link'>0 0 -0.12 -1.5708 0 0</pose>
      <parent>front_left_steer_link</parent>
      <child>front_left_wheel_link</child>
      <axis>
        <xyz>0 0 1</xyz>
        <limit>
          <lower>-1e+16</lower>
          <upper>1e+16</upper>
        </limit>
        <dynamics>
          <spring_reference>0</spring_reference>
          <spring_stiffness>0</spring_stiffness>
        </dynamics>
      </axis>
    </joint>
    <link name='front_left_wheel_link'>
      <pose relative_to='front_left_wheel_joint'>0 0 0 0 -0 0</pose>
      <inertial>
        <pose>0 0 0 0 -0 0</pose>
        <mass>1</mass>
        <inertia>
          <ixx>0.00303333</ixx>
          <ixy>0</ixy>
          <ixz>0</ixz>
          <iyy>0.00303333</iyy>
          <iyz>0</iyz>
          <izz>0.005</izz>
        </inertia>
      </inertial>
      <collision name='front_left_wheel_link_collision'>
        <pose>0 0 0 0 -0 0</pose>
        <geometry>
          <cylinder>
            <length>0.08</length>
            <radius>0.1</radius>
          </cylinder>
        </geometry>
        <surface>
          <contact>
            <ode/>
          </contact>
          <friction>
            <ode/>
          </friction>
        </surface>
      </collision>
      <visual name='front_left_wheel_link_visual'>
        <pose>0 0 0 0 -0 0</pose>
        <geometry>
          <cylinder>
            <length>0.08</length>
            <radius>0.1</radius>
          </cylinder>
        </geometry>
        <material>
          <script>
            <name>Gazebo/Red</name>
            <uri>file://media/materials/scripts/gazebo.material</uri>
          </script>
        </material>
      </visual>
      <gravity>1</gravity>
      <velocity_decay/>
    </link>
    <joint name='front_right_steer_joint' type='revolute'>
      <pose relative_to='base_link'>0.2 -0.2 0.12 0 -0 0</pose>
      <parent>base_link</parent>
      <child>front_right_steer_link</child>
      <axis>
        <xyz>0 0 1</xyz>
        <limit>
          <lower>-0.785398</lower>
          <upper>0.785398</upper>
          <effort>10</effort>
          <velocity>5</velocity>
        </limit>
        <dynamics>
          <spring_reference>0</spring_reference>
          <spring_stiffness>0</spring_stiffness>
        </dynamics>
      </axis>
    </joint>
    <link name='front_right_steer_link'>
      <pose relative_to='front_right_steer_joint'>0 0 0 0 -0 0</pose>
      <inertial>
        <pose>0 0 0 0 -0 0</pose>
        <mass>1</mass>
        <inertia>
          <ixx>0.000658333</ixx>
          <ixy>0</ixy>
          <ixz>0</ixz>
          <iyy>0.000658333</iyy>
          <iyz>0</iyz>
          <izz>0.00125</izz>
        </inertia>
      </inertial>
      <collision name='front_right_steer_link_collision'>
        <pose>0 0 0 0 -0 0</pose>
        <geometry>
          <cylinder>
            <length>0.02</length>
            <radius>0.05</radius>
          </cylinder>
        </geometry>
        <surface>
          <contact>
            <ode/>
          </contact>
          <friction>
            <ode/>
          </friction>
        </surface>
      </collision>
      <visual name='front_right_steer_link_visual'>
        <pose>0 0 0 0 -0 0</pose>
        <geometry>
          <cylinder>
            <length>0.02</length>
            <radius>0.05</radius>
          </cylinder>
        </geometry>
        <material>
          <script>
            <name>Gazebo/Blue</name>
            <uri>file://media/materials/scripts/gazebo.material</uri>
          </script>
        </material>
      </visual>
      <gravity>1</gravity>
      <velocity_decay/>
    </link>
    <joint name='front_right_wheel_joint' type='revolute'>
      <pose relative_to='front_right_steer_link'>0 0 -0.12 -1.5708 0 0</pose>
      <parent>front_right_steer_link</parent>
      <child>front_right_wheel_link</child>
      <axis>
        <xyz>0 0 1</xyz>
        <limit>
          <lower>-1e+16</lower>
          <upper>1e+16</upper>
        </limit>
        <dynamics>
          <spring_reference>0</spring_reference>
          <spring_stiffness>0</spring_stiffness>
        </dynamics>
      </axis>
    </joint>
    <link name='front_right_wheel_link'>
      <pose relative_to='front_right_wheel_joint'>0 0 0 0 -0 0</pose>
      <inertial>
        <pose>0 0 0 0 -0 0</pose>
        <mass>1</mass>
        <inertia>
          <ixx>0.00303333</ixx>
          <ixy>0</ixy>
          <ixz>0</ixz>
          <iyy>0.00303333</iyy>
          <iyz>0</iyz>
          <izz>0.005</izz>
        </inertia>
      </inertial>
      <collision name='front_right_wheel_link_collision'>
        <pose>0 0 0 0 -0 0</pose>
        <geometry>
          <cylinder>
            <length>0.08</length>
            <radius>0.1</radius>
          </cylinder>
        </geometry>
        <surface>
          <contact>
            <ode/>
          </contact>
          <friction>
            <ode/>
          </friction>
        </surface>
      </collision>
      <visual name='front_right_wheel_link_visual'>
        <pose>0 0 0 0 -0 0</pose>
        <geometry>
          <cylinder>
            <length>0.08</length>
            <radius>0.1</radius>
          </cylinder>
        </geometry>
        <material>
          <script>
            <name>Gazebo/Red</name>
            <uri>file://media/materials/scripts/gazebo.material</uri>
          </script>
        </material>
      </visual>
      <gravity>1</gravity>
      <velocity_decay/>
    </link>
    <joint name='front_steer_joint' type='revolute'>
      <pose relative_to='base_link'>0.2 0 0.12 0 -0 0</pose>
      <parent>base_link</parent>
      <child>front_steer_link</child>
      <axis>
        <xyz>0 0 1</xyz>
        <limit>
          <lower>-3.14159</lower>
          <upper>3.14159</upper>
          <effort>10</effort>
          <velocity>5</velocity>
        </limit>
        <dynamics>
          <spring_reference>0</spring_reference>
          <spring_stiffness>0</spring_stiffness>
        </dynamics>
      </axis>
    </joint>
    <link name='front_steer_link'>
      <pose relative_to='front_steer_joint'>0 0 0 0 -0 0</pose>
      <inertial>
        <pose>0 0 0 0 -0 0</pose>
        <mass>1</mass>
        <inertia>
          <ixx>0.000658333</ixx>
          <ixy>0</ixy>
          <ixz>0</ixz>
          <iyy>0.000658333</iyy>
          <iyz>0</iyz>
          <izz>0.00125</izz>
        </inertia>
      </inertial>
      <collision name='front_steer_link_collision'>
        <pose>0 0 0 0 -0 0</pose>
        <geometry>
          <cylinder>
            <length>0.02</length>
            <radius>0.05</radius>
          </cylinder>
        </geometry>
        <surface>
          <contact>
            <ode/>
          </contact>
          <friction>
            <ode/>
          </friction>
        </surface>
      </collision>
      <visual name='front_steer_link_visual'>
        <pose>0 0 0 0 -0 0</pose>
        <geometry>
          <cylinder>
            <length>0.02</length>
            <radius>0.05</radius>
          </cylinder>
        </geometry>
        <material>
          <script>
            <name>Gazebo/Yellow</name>
            <uri>file://media/materials/scripts/gazebo.material</uri>
          </script>
        </material>
      </visual>
      <gravity>1</gravity>
      <velocity_decay/>
    </link>
    <joint name='rear_left_wheel_joint' type='revolute'>
      <pose relative_to='base_link'>-0.2 0.2 0 -1.5708 0 0</pose>
      <parent>base_link</parent>
      <child>rear_left_wheel_link</child>
      <axis>
        <xyz>0 0 1</xyz>
        <limit>
          <lower>-1e+16</lower>
          <upper>1e+16</upper>
        </limit>
        <dynamics>
          <spring_reference>0</spring_reference>
          <spring_stiffness>0</spring_stiffness>
        </dynamics>
      </axis>
    </joint>
    <link name='rear_left_wheel_link'>
      <pose relative_to='rear_left_wheel_joint'>0 0 0 0 -0 0</pose>
      <inertial>
        <pose>0 0 0 0 -0 0</pose>
        <mass>1</mass>
        <inertia>
          <ixx>0.00303333</ixx>
          <ixy>0</ixy>
          <ixz>0</ixz>
          <iyy>0.00303333</iyy>
          <iyz>0</iyz>
          <izz>0.005</izz>
        </inertia>
      </inertial>
      <collision name='rear_left_wheel_link_collision'>
        <pose>0 0 0 0 -0 0</pose>
        <geometry>
          <cylinder>
            <length>0.08</length>
            <radius>0.1</radius>
          </cylinder>
        </geometry>
        <surface>
          <contact>
            <ode/>
          </contact>
          <friction>
            <ode/>
          </friction>
        </surface>
      </collision>
      <visual name='rear_left_wheel_link_visual'>
        <pose>0 0 0 0 -0 0</pose>
        <geometry>
          <cylinder>
            <length>0.08</length>
            <radius>0.1</radius>
          </cylinder>
        </geometry>
        <material>
          <script>
            <name>Gazebo/Red</name>
            <uri>file://media/materials/scripts/gazebo.material</uri>
          </script>
        </material>
      </visual>
      <gravity>1</gravity>
      <velocity_decay/>
    </link>
    <joint name='rear_right_wheel_joint' type='revolute'>
      <pose relative_to='base_link'>-0.2 -0.2 0 -1.5708 0 0</pose>
      <parent>base_link</parent>
      <child>rear_right_wheel_link</child>
      <axis>
        <xyz>0 0 1</xyz>
        <limit>
          <lower>-1e+16</lower>
          <upper>1e+16</upper>
        </limit>
        <dynamics>
          <spring_reference>0</spring_reference>
          <spring_stiffness>0</spring_stiffness>
        </dynamics>
      </axis>
    </joint>
    <link name='rear_right_wheel_link'>
      <pose relative_to='rear_right_wheel_joint'>0 0 0 0 -0 0</pose>
      <inertial>
        <pose>0 0 0 0 -0 0</pose>
        <mass>1</mass>
        <inertia>
          <ixx>0.00303333</ixx>
          <ixy>0</ixy>
          <ixz>0</ixz>
          <iyy>0.00303333</iyy>
          <iyz>0</iyz>
          <izz>0.005</izz>
        </inertia>
      </inertial>
      <collision name='rear_right_wheel_link_collision'>
        <pose>0 0 0 0 -0 0</pose>
        <geometry>
          <cylinder>
            <length>0.08</length>
            <radius>0.1</radius>
          </cylinder>
        </geometry>
        <surface>
          <contact>
            <ode/>
          </contact>
          <friction>
            <ode/>
          </friction>
        </surface>
      </collision>
      <visual name='rear_right_wheel_link_visual'>
        <pose>0 0 0 0 -0 0</pose>
        <geometry>
          <cylinder>
            <length>0.08</length>
            <radius>0.1</radius>
          </cylinder>
        </geometry>
        <material>
          <script>
            <name>Gazebo/Red</name>
            <uri>file://media/materials/scripts/gazebo.material</uri>
          </script>
        </material>
      </visual>
      <gravity>1</gravity>
      <velocity_decay/>
    </link>
    <joint name='rear_wheel_joint' type='revolute'>
      <pose relative_to='base_link'>-0.2 0 0 -1.5708 0 0</pose>
      <parent>base_link</parent>
      <child>rear_wheel_link</child>
      <axis>
        <xyz>0 0 1</xyz>
        <limit>
          <lower>-1e+16</lower>
          <upper>1e+16</upper>
        </limit>
        <dynamics>
          <spring_reference>0</spring_reference>
          <spring_stiffness>0</spring_stiffness>
        </dynamics>
      </axis>
    </joint>
    <link name='rear_wheel_link'>
      <pose relative_to='rear_wheel_joint'>0 0 0 0 -0 0</pose>
      <inertial>
        <pose>0 0 0 0 -0 0</pose>
        <mass>0.03125</mass>
        <inertia>
          <ixx>9.04948e-06</ixx>
          <ixy>0</ixy>
          <ixz>0</ixz>
          <iyy>9.04948e-06</iyy>
          <iyz>0</iyz>
          <izz>9.76563e-06</izz>
        </inertia>
      </inertial>
      <collision name='rear_wheel_link_collision'>
        <pose>0 0 0 0 -0 0</pose>
        <geometry>
          <cylinder>
            <length>0.04</length>
            <radius>0.025</radius>
          </cylinder>
        </geometry>
        <surface>
          <contact>
            <ode/>
          </contact>
          <friction>
            <ode/>
          </friction>
        </surface>
      </collision>
      <visual name='rear_wheel_link_visual'>
        <pose>0 0 0 0 -0 0</pose>
        <geometry>
          <cylinder>
            <length>0.04</length>
            <radius>0.025</radius>
          </cylinder>
        </geometry>
        <material>
          <script>
            <name>Gazebo/Yellow</name>
            <uri>file://media/materials/scripts/gazebo.material</uri>
          </script>
        </material>
      </visual>
      <gravity>1</gravity>
      <velocity_decay/>
    </link>
    <static>0</static>
  </model>
</sdf>
