<sdf version="1.6">
  <model name="thrust_stand">
    <link name="base_link">
      <collision name="collision">
        <geometry>
          <box>
            <size>0.1 0.1 0.2</size>
          </box>
        </geometry>
      </collision>
      <visual name="visual">
        <geometry>
          <box>
            <size>0.1 0.1 0.2</size>
          </box>
        </geometry>
        <material>
          <script>
            <name>Gazebo/Red</name>
            <uri>file://media/materials/scripts/gazebo.material</uri>
          </script>
        </material>
      </visual>
      <inertial>
        <inertia>
          <ixx>0.4166666666666667</ixx>
          <iyy>0.4166666666666667</iyy>
          <izz>0.16666666666666669</izz>
          <ixy>0.0</ixy>
          <ixz>0.0</ixz>
          <iyz>0.0</iyz>
        </inertia>
        <pose frame="">0 0 0 0 -0 0</pose>
        <mass>100.0</mass>
      </inertial>
    </link>
    <link name="imu_link">
      <sensor name="imu_sensor" type="imu">
        <imu/>
        <pose frame="">0 0 0 3.14159 0 0</pose>
        <always_on>1</always_on>
        <update_rate>50.0</update_rate>
      </sensor>
      <inertial>
        <inertia>
          <ixx>1.6666666666666668e-07</ixx>
          <iyy>1.6666666666666668e-07</iyy>
          <izz>1.6666666666666668e-07</izz>
          <ixy>0.0</ixy>
          <ixz>0.0</ixz>
          <iyz>0.0</iyz>
        </inertia>
        <pose frame="">0 0 0 0 -0 0</pose>
        <mass>0.01</mass>
      </inertial>
    </link>
    <link name="motor_link">
      <pose frame="">-0.06375 0 0.073 0 -1.5708 0</pose>
      <collision name="collision">
        <geometry>
          <cylinder>
            <radius>0.0135</radius>
            <length>0.0275</length>
          </cylinder>
        </geometry>
      </collision>
      <visual name="visual">
        <geometry>
          <cylinder>
            <radius>0.0135</radius>
            <length>0.0275</length>
          </cylinder>
        </geometry>
        <material>
          <script>
            <name>Gazebo/Orange</name>
            <uri>file://media/materials/scripts/gazebo.material</uri>
          </script>
        </material>
      </visual>
      <visual name="prop_visual">
        <geometry>
          <mesh>
            <uri>/Users/rhys/CloudStation/Projects/GazeboPhysics/meshes/propeller_9x4.7.stl</uri>
            <scale>1 1 1</scale>
          </mesh>
        </geometry>
        <material>
          <script>
            <name>Gazebo/Green</name>
            <uri>file://media/materials/scripts/gazebo.material</uri>
          </script>
        </material>
      </visual>
      <inertial>
        <inertia>
          <ixx>5.211999999999999e-06</ixx>
          <iyy>5.211999999999999e-06</iyy>
          <izz>4.374e-06</izz>
          <ixy>0.0</ixy>
          <ixz>0.0</ixz>
          <iyz>0.0</iyz>
        </inertia>
        <pose frame="">0 0 0 0 -0 0</pose>
        <mass>0.048</mass>
      </inertial>
    </link>
    <joint name="motor_joint" type="revolute">
      <parent>base_link</parent>
      <child>motor_link</child>
      <axis>
        <xyz>0 0 1</xyz>
        <limit>
          <lower>-1e+16</lower>
          <upper>1e+16</upper>
        </limit>
        <dynamics>
          <spring_reference>0</spring_reference>
          <spring_stiffness>0</spring_stiffness>
          <damping>0.0001</damping>
          <friction>0.0001</friction>
        </dynamics>
      </axis>
      <sensor name="force_torque_sensor" type="force_torque">
        <always_on>1</always_on>
        <update_rate>30.0</update_rate>
        <visualize>1</visualize>
      </sensor>
    </joint>
    <joint name="imu_joint" type="revolute">
      <parent>base_link</parent>
      <child>imu_link</child>
      <axis>
        <xyz>0 0 1</xyz>
        <limit>
          <lower>-1e+16</lower>
          <upper>1e+16</upper>
        </limit>
      </axis>
    </joint>
    <plugin name="prop_blade_1_liftdrag" filename="libLiftDragPlugin.so">
      <a0>0.3</a0>
      <alpha_stall>1.4</alpha_stall>
      <cla>4.25</cla>
      <cda>0.1</cda>
      <cma>0</cma>
      <cla_stall>-0.025</cla_stall>
      <cda_stall>0</cda_stall>
      <cma_stall>0</cma_stall>
      <area>0.002</area>
      <air_density>1.2041</air_density>
      <cp>0.084 0 0</cp>
      <forward>0 1.0 0</forward>
      <upward>0 0 1</upward>
      <link_name>motor_link</link_name>
    </plugin>
    <plugin name="prop_blade_2_liftdrag" filename="libLiftDragPlugin.so">
      <a0>0.3</a0>
      <alpha_stall>1.4</alpha_stall>
      <cla>4.25</cla>
      <cda>0.1</cda>
      <cma>0</cma>
      <cla_stall>-0.025</cla_stall>
      <cda_stall>0</cda_stall>
      <cma_stall>0</cma_stall>
      <area>0.002</area>
      <air_density>1.2041</air_density>
      <cp>-0.084 0 0</cp>
      <forward>0 -1.0 0</forward>
      <upward>0 0 1</upward>
      <link_name>motor_link</link_name>
    </plugin>
    <plugin name="ardupilot_plugin" filename="libArduPilotPlugin.so">
      <fdm_addr>127.0.0.1</fdm_addr>
      <fdm_port_in>9002</fdm_port_in>
      <connectionTimeoutMaxCount>5</connectionTimeoutMaxCount>
      <modelXYZToAirplaneXForwardZDown>0 0 0 3.141592653589793 0 0</modelXYZToAirplaneXForwardZDown>
      <gazeboXYZToNED>0 0 0 3.141592653589793 0 0</gazeboXYZToNED>
      <imuName>imu_link::imu_sensor</imuName>
      <control channel="2">
        <jointName>motor_joint</jointName>
        <useForce>1</useForce>
        <multiplier>-800</multiplier>
        <offset>0</offset>
        <servo_min>1000</servo_min>
        <servo_max>2000</servo_max>
        <type>VELOCITY</type>
        <p_gain>0.001</p_gain>
        <i_gain>0</i_gain>
        <d_gain>0</d_gain>
        <i_max>0.1</i_max>
        <i_min>-0.1</i_min>
        <cmd_max>5.0</cmd_max>
        <cmd_min>-5.0</cmd_min>
      </control>
    </plugin>
  </model>
</sdf>